<?xml version="1.0" ?><!-- =================================================================================== --><!-- |    This document was autogenerated by xacro from urdf/robot_arm.urdf.xacro      | --><!-- |    EDITING THIS FILE BY HAND IS NOT RECOMMENDED                                 | --><!-- =================================================================================== --><robot name="robot_arm"><!-- =====================================================================
       robot_arm.urdf.xacro
       Industrial Robotics TP — Master 1 Robotics & Embedded Systems
       Robot: 4-DOF robotic arm with parallel gripper
       Architecture: Xacro (modular macros, includes, parameter reuse)
  ====================================================================== --><!-- ================================================================
       LINKS
  ================================================================ --><!-- 1. world (virtual fixed origin) --><link name="world"/><!-- 2. base_link (basement / motor base) --><link name="base_link"><inertial><origin rpy="0 0 0" xyz="0 0 0"/><mass value="1.0"/><inertia ixx="0.0011333333333333334" ixy="0" ixz="0" iyy="0.0011333333333333334" iyz="0" izz="0.001666666666666667"/></inertial><visual><origin rpy="0 0 0" xyz="-0.5 -0.5 0"/><geometry><mesh filename="package://robot_arm_description/meshes/basement.stl" scale="0.01 0.01 0.01"/></geometry><material name="white"><color rgba="0.9 0.9 0.9 1"/></material></visual><collision><origin rpy="0 0 0" xyz="0 0 0.03"/><geometry><cylinder length="0.06" radius="0.05"/></geometry></collision></link><!-- 3. base_plate (rotating shoulder base) --><link name="base_plate"><inertial><origin rpy="0 0 0" xyz="0 0 0"/><mass value="0.5"/><inertia ixx="0.00030416666666666667" ixy="0" ixz="0" iyy="0.00030416666666666667" iyz="0" izz="0.0005333333333333334"/></inertial><visual><origin rpy="0 0 0" xyz="-0.39 -0.39 -0.56"/><geometry><mesh filename="package://robot_arm_description/meshes/base_plate.stl" scale="0.01 0.01 0.01"/></geometry><material name="blue_dark"><color rgba="0.1 0.1 0.6 1"/></material></visual><collision><origin rpy="0 0 0" xyz="0 0 0"/><geometry><cylinder length="0.03" radius="0.04"/></geometry></collision></link><!-- 4. forward_drive_arm (first arm segment, vertical) --><link name="forward_drive_arm"><inertial><origin rpy="0 0 0" xyz="0 0 0"/><mass value="0.3"/><inertia ixx="0.00019999999999999998" ixy="0" ixz="0" iyy="0.00019999999999999998" iyz="0" izz="8e-05"/></inertial><visual><origin rpy="0 -1.570796326794895 1.570796326794895" xyz="0.19 0.06 -0.08"/><geometry><mesh filename="package://robot_arm_description/meshes/forward_drive_arm.stl" scale="0.01 0.01 0.01"/></geometry><material name="grey_light"><color rgba="0.75 0.75 0.75 1"/></material></visual><collision><origin rpy="0 0 0" xyz="0 0 0.04"/><geometry><box size="0.04 0.04 0.08"/></geometry></collision></link><!-- 5. horizontal_arm (second arm segment, horizontal reach) --><link name="horizontal_arm"><inertial><origin rpy="0 0 0" xyz="0 0 0"/><mass value="0.25"/><inertia ixx="6.666666666666667e-05" ixy="0" ixz="0" iyy="0.00016666666666666666" iyz="0" izz="0.00016666666666666666"/></inertial><visual><origin rpy="1.570796326794895 0 1.570796326794895" xyz="-0.03 -0.4 -0.06"/><geometry><mesh filename="package://robot_arm_description/meshes/horizontal_arm.stl" scale="0.01 0.01 0.01"/></geometry><material name="grey_light"/></visual><collision><origin rpy="0 0 0" xyz="0.04 0 0"/><geometry><box size="0.08 0.04 0.04"/></geometry></collision></link><!-- 6. claw_support (wrist / end-effector mounting plate) --><link name="claw_support"><inertial><origin rpy="0 0 0" xyz="0 0 0"/><mass value="0.15"/><inertia ixx="2.4999999999999998e-05" ixy="0" ixz="0" iyy="2.4999999999999998e-05" iyz="0" izz="4e-05"/></inertial><visual><origin rpy="0 0 1.570796326794895" xyz="0 -0.05 -0.15"/><geometry><mesh filename="package://robot_arm_description/meshes/claw_support.stl" scale="0.01 0.01 0.01"/></geometry><material name="grey_dark"><color rgba="0.4 0.4 0.4 1"/></material></visual><collision><origin rpy="0 0 0" xyz="0 0 0"/><geometry><box size="0.04 0.04 0.02"/></geometry></collision></link><!-- 7. gripper_right (right finger — actively controlled, joint4) --><link name="gripper_right"><inertial><origin rpy="0 0 0" xyz="0 0 0"/><mass value="0.05"/><inertia ixx="1.7333333333333336e-06" ixy="0" ixz="0" iyy="2.3708333333333336e-06" iyz="0" izz="7.708333333333334e-07"/></inertial><visual><origin rpy="0 0 -1.570796326794895" xyz="-0.1 0.5 -0.1"/><geometry><mesh filename="package://robot_arm_description/meshes/right_finger.stl" scale="0.01 0.01 0.01"/></geometry><material name="blue_dark"/></visual><collision><origin rpy="0 0 0" xyz="0 0 0.01"/><geometry><box size="0.013 0.004 0.02"/></geometry></collision></link><!-- 8. gripper_left (left finger — mirrors joint4 via mimic) --><link name="gripper_left"><inertial><origin rpy="0 0 0" xyz="0 0 0"/><mass value="0.05"/><inertia ixx="1.7333333333333336e-06" ixy="0" ixz="0" iyy="2.3708333333333336e-06" iyz="0" izz="7.708333333333334e-07"/></inertial><visual><origin rpy="0 0 -1.570796326794895" xyz="-0.04 0.5 -0.1"/><geometry><mesh filename="package://robot_arm_description/meshes/left_finger.stl" scale="0.01 0.01 0.01"/></geometry><material name="blue_dark"/></visual><collision><origin rpy="0 0 0" xyz="0 0 0.01"/><geometry><box size="0.013 0.004 0.02"/></geometry></collision></link><!-- ================================================================
       JOINTS
  ================================================================ --><!-- J0 — world → base_link  (fixed: robot bolted to ground) --><joint name="world_to_base" type="fixed"><parent link="world"/><child link="base_link"/><origin rpy="0 0 0" xyz="0 0 0"/></joint><!-- J1 — base_link → base_plate  (revolute: waist rotation around Z)
       Height offset: 3.07 cm (from TP diagram) --><joint name="joint1" type="revolute"><parent link="base_link"/><child link="base_plate"/><origin rpy="0 0 0" xyz="0 0 0.0307"/><axis xyz="0 0 1"/><limit effort="100" lower="-1.570796326794895" upper="1.570796326794895" velocity="1.0"/></joint><!-- J2 — base_plate → forward_drive_arm  (revolute: shoulder pitch around Y)
       Height offset: 3.5 cm (from TP diagram) --><joint name="joint2" type="revolute"><parent link="base_plate"/><child link="forward_drive_arm"/><origin rpy="0 0 0" xyz="0 0 0.035"/><axis xyz="1 0 0"/><limit effort="100" lower="-1.570796326794895" upper="1.570796326794895" velocity="1.0"/></joint><!-- J3 — forward_drive_arm → horizontal_arm  (revolute: elbow pitch around Y)
       Height offset: 8 cm (from TP diagram) --><joint name="joint3" type="revolute"><parent link="forward_drive_arm"/><child link="horizontal_arm"/><origin rpy="0 0 0" xyz="0 0 0.08"/><axis xyz="1 0 0"/><limit effort="100" lower="-1.570796326794895" upper="1.570796326794895" velocity="1.0"/></joint><!-- J_claw — horizontal_arm → claw_support  (revolute: wrist rotation)
       Horizontal offset: 8.2 cm (from TP diagram) --><joint name="joint_claw" type="revolute"><parent link="horizontal_arm"/><child link="claw_support"/><origin rpy="0 0 0" xyz="0.082 0 0"/><axis xyz="0 0 1"/><limit effort="50" lower="-1.570796326794895" upper="1.570796326794895" velocity="1.0"/></joint><!-- J4 — claw_support → gripper_right  (prismatic: finger open/close)
       Range: 0 → 2.2 cm, offset 1 cm up (from TP diagram) --><joint name="joint4" type="prismatic"><parent link="claw_support"/><child link="gripper_right"/><origin rpy="0 0 0" xyz="0 0 0.01"/><axis xyz="1 0 0"/><limit effort="20" lower="0" upper="0.022" velocity="0.5"/></joint><!-- J_left — claw_support → gripper_left  (prismatic: mirrors joint4) --><joint name="joint_gripper_left" type="prismatic"><parent link="claw_support"/><child link="gripper_left"/><origin rpy="0 0 0" xyz="0 0 0.01"/><axis xyz="-1 0 0"/><limit effort="20" lower="0" upper="0.022" velocity="0.5"/><!-- Mirror: left finger closes when right opens --><mimic joint="joint4" multiplier="-1"/></joint></robot>